Workbook

Sheet Answer Report 1
A1: Microsoft Excel 16.0 Answer Report
A2: Worksheet: [PCReg_Template_v3.xlsx]Model
A3: Report Created: 2/7/2026 2:25:13 PM
A4: Result: Solver has converged to the current solution. All Constraints are satisfied.
A5: Solver Engine
B6: Engine: GRG Nonlinear
B7: Solution Time: 1.031 Seconds.
B8: Iterations: 14 Subproblems: 0
A9: Solver Options
B10: Max Time Unlimited, Iterations Unlimited, Precision 0.000001
B11: Convergence 0.0001, Population Size 100, Random Seed 0, Derivatives Central
B12: Max Subproblems Unlimited, Max Integer Sols Unlimited, Integer Tolerance 1%, Assume NonNegative
A14: Objective Cell (Min)
B15: Cell | C15: Name | D15: Original Value | E15: Final Value
B16: $C$16 | C16: (Minimize) YES or NO | D16: 442500 | E16: 197.54216
A19: Variable Cells
B20: Cell | C20: Name | D20: Original Value | E20: Final Value | F20: Integer
B21: $C$35:$L$35
B22: $C$35 | C22: Value Intercept | D22: 100 | E22: 813.6692 | F22: Contin
B23: $D$35 | C23: Value β₁ (LC) | D23: 0 | E23: -0.10997977 | F23: Contin
B24: $E$35 | C24: Value β₂ (RC) | D24: 0 | E24: -0.13256892 | F24: Contin
B25: $F$35 | C25: Value β₃ | D25: 0 | E25: 0 | F25: Contin
B26: $G$35 | C26: Value β₄ | D26: 0 | E26: 0 | F26: Contin
B27: $H$35 | C27: Value | D27: 0 | E27: 0 | F27: Contin
B28: $I$35 | C28: Value | D28: 0 | E28: 0 | F28: Contin
B29: $J$35 | C29: Value | D29: 0 | E29: 0 | F29: Contin
B30: $K$35 | C30: Value | D30: 0 | E30: 0 | F30: Contin
B31: $L$35 | C31: Value | D31: 0 | E31: 0 | F31: Contin
A35: Constraints
B36: Cell | C36: Name | D36: Cell Value | E36: Formula | F36: Status | G36: Slack
B37: $C$35:$L$35 <= $C$37:$L$37
B38: $C$35 | C38: Value Intercept | D38: 813.6692 | E38: $C$35<=$C$37 | F38: Not Binding | G38: 9.9999992e+09
B39: $D$35 | C39: Value β₁ (LC) | D39: -0.10997977 | E39: $D$35<=$D$37 | F39: Not Binding | G39: 0.10997977
B40: $E$35 | C40: Value β₂ (RC) | D40: -0.13256892 | E40: $E$35<=$E$37 | F40: Not Binding | G40: 0.13256892
B41: $F$35 | C41: Value β₃ | D41: 0 | E41: $F$35<=$F$37 | F41: Binding | G41: 0
B42: $G$35 | C42: Value β₄ | D42: 0 | E42: $G$35<=$G$37 | F42: Binding | G42: 0
B43: $H$35 | C43: Value | D43: 0 | E43: $H$35<=$H$37 | F43: Binding | G43: 0
B44: $I$35 | C44: Value | D44: 0 | E44: $I$35<=$I$37 | F44: Binding | G44: 0
B45: $J$35 | C45: Value | D45: 0 | E45: $J$35<=$J$37 | F45: Binding | G45: 0
B46: $K$35 | C46: Value | D46: 0 | E46: $K$35<=$K$37 | F46: Binding | G46: 0
...

Sheet Sensitivity Report 1
A1: Microsoft Excel 16.0 Sensitivity Report
A2: Worksheet: [PCReg_Template_v3.xlsx]Model
A3: Report Created: 2/7/2026 2:25:17 PM
A6: Variable Cells
D7: Final | E7: Reduced
B8: Cell | C8: Name | D8: Value | E8: Gradient
B9: $C$35:$L$35
B10: $C$35 | C10: Value Intercept | D10: 813.6692 | E10: 0
B11: $D$35 | C11: Value β₁ (LC) | D11: -0.10997977 | E11: 0
B12: $E$35 | C12: Value β₂ (RC) | D12: -0.13256892 | E12: 0
B13: $F$35 | C13: Value β₃ | D13: 0 | E13: 0
B14: $G$35 | C14: Value β₄ | D14: 0 | E14: 0
B15: $H$35 | C15: Value | D15: 0 | E15: 0
B16: $I$35 | C16: Value | D16: 0 | E16: 0
B17: $J$35 | C17: Value | D17: 0 | E17: 0
B18: $K$35 | C18: Value | D18: 0 | E18: 0
B19: $L$35 | C19: Value | D19: 0 | E19: 0
A22: Constraints
B23: NONE

Sheet Limits Report 1
A1: Microsoft Excel 16.0 Limits Report
A2: Worksheet: [PCReg_Template_v3.xlsx]Model
A3: Report Created: 2/7/2026 2:25:18 PM
C6: Objective
B7: Cell | C7: Name | D7: Value
B8: $C$16 | C8: (Minimize) YES or NO | D8: 197.54216
C11: Variable | F11: Lower | G11: Objective | I11: Upper | J11: Objective
B12: Cell | C12: Name | D12: Value | F12: Limit | G12: Result | I12: Limit | J12: Result
B13: $C$35:$L$35
B14: $C$35 | C14: Value Intercept | D14: 813.6692 | F14: 0 | G14: 782500.01 | I14: #N/A | J14: #N/A
B15: $D$35 | C15: Value β₁ (LC) | D15: -0.10997977 | F15: 0 | G15: 139690.52 | I15: 0 | J15: 139690.52
B16: $E$35 | C16: Value β₂ (RC) | D16: -0.13256892 | F16: 0 | G16: 160856.99 | I16: 0 | J16: 160856.99
B17: $F$35 | C17: Value β₃ | D17: 0 | F17: 0 | G17: 197.54216 | I17: 0 | J17: 197.54216
B18: $G$35 | C18: Value β₄ | D18: 0 | F18: 0 | G18: 197.54216 | I18: 0 | J18: 197.54216
B19: $H$35 | C19: Value | D19: 0 | F19: 0 | G19: 197.54216 | I19: 0 | J19: 197.54216
B20: $I$35 | C20: Value | D20: 0 | F20: 0 | G20: 197.54216 | I20: 0 | J20: 197.54216
B21: $J$35 | C21: Value | D21: 0 | F21: 0 | G21: 197.54216 | I21: 0 | J21: 197.54216
B22: $K$35 | C22: Value | D22: 0 | F22: 0 | G22: 197.54216 | I22: 0 | J22: 197.54216
B23: $L$35 | C23: Value | D23: 0 | F23: 0 | G23: 197.54216 | I23: 0 | J23: 197.54216

Sheet Model
A1: Penalized-Constrained Regression Template
A2: minimize L(β) + α·l1_ratio·Σ|βⱼ| + ½·α·(1−l1_ratio)·Σβⱼ² s.t. LB ≤ β ≤ UB, Aβ ≤ b
A4: HYPERPARAMETERS
A5: Alpha (α) | B5: 0.1 | C5: Overall penalty strength (0 = constrained-only, no penalty)
A6: L1 Ratio | B6: 0.5 | C6: 0=Ridge, 0.5=ElasticNet, 1=Lasso
A7: Loss Function | B7: SSE | C7: SSE | SSPE | LAD
A8: Fit Intercept | B8: YES | C8: YES or NO
A10: OBJECTIVE FUNCTION
A11: Total Loss | B11: (weighted) | C11: {=SUMPRODUCT(IF(pcreg_DataTable[Include]="",0,pcreg_DataTable[Include])*(pcreg_DataTable[Loss_i]))} -> 197.52929
A12: L1 Penalty | C12: =B44 -> 0.012127435
A13: L2 Penalty | C13: =B45 -> 0.00074175173
A14: Total Penalty | C14: =C12+C13 -> 0.012869186
A16: ★ OBJECTIVE | B16: (Minimize) | C16: =C11+C14 -> 197.54216
A17: n (obs) | B17: =SUM(pcreg_DataTable[Include]) -> 5
A18: p (coefs) | B18: =SUM(C46:L46) -> 3
A19: Binding Constraints | B19: =SUM(C47:L47) -> 0
A20: GDF | B20: =B17-B18-B19 -> 2
A22: SOLVER SETUP INSTRUCTIONS
A23: 1. Build your ŷ formula in column D referencing coefficient values in row 35.
A24: Example: =IF($B$8="YES",$C$35,0) + F54*$D$35 + G54*$E$35
A25: Log-linear: =EXP($C$35 + LN(F54)*$D$35 + LN(G54)*$E$35)
A26: 2. Copy the ŷ formula down for all data rows.
A27: 3. Open Solver (Data → Solver).
A28: 4. Set Objective: $C$16 | To: Min
A29: 5. By Changing Variable Cells: $C$35:$L$35
A30: 6. Add Constraint: $C$35:$L$35 >= $C$36:$L$36 (lower bounds)
A31: 7. Add Constraint: $C$35:$L$35 <= $C$37:$L$37 (upper bounds)
A32: 8. For custom Aβ constraints, reference LHS/RHS in the Constraints table (rows 46-48).
A33: 9. Solving Method: GRG Nonlinear
... A36: COEFFICIENTS
A37: Coefficient → | B37: Totals | C37: Intercept | D37: β₁ (LC) | E37: β₂ (RC) | F37: β₃ | G37: β₄
A38: Value | C38: 813.6692 | D38: -0.10997977 | E38: -0.13256892 | F38: 0 | G38: 0 | H38: 0 | I38: 0 | J38: 0 | K38: 0 | L38: 0
A39: Lower Bound | C39: 0 | D39: -1 | E39: -1 | F39: 0 | G39: 0 | H39: 0 | I39: 0 | J39: 0 | K39: 0 | L39: 0
A40: Upper Bound | C40: 10000000000 | D40: 0 | E40: 0 | F40: 0 | G40: 0 | H40: 0 | I40: 0 | J40: 0 | K40: 0 | L40: 0
A41: Penalized? | C41: NO | D41: YES | E41: YES | F41: YES | G41: YES
A42: |β| | B42: =SUM(C42:L42) -> 813.91175 | C42: =IF(C37="","",ABS(C38)) -> 813.6692 | D42: =IF(D37="","",ABS(D38)) -> 0.10997977 | E42: =IF(E37="","",ABS(E38)) -> 0.13256892 | F42: =IF(F37="","",ABS(F38)) -> 0 | G42: =IF(G37="","",ABS(G38)) -> 0 | H42: =IF(H37="","",ABS(H38)) | I42: =IF(I37="","",ABS(I38)) | J42: =IF(J37="","",ABS(J38)) | ... L42: =IF(L37="","",ABS(L38))
A43: β² | B43: =SUM(C43:L43) -> 662057.6 | C43: =IF(C37="","",C38^2) -> 662057.57 | D43: =IF(D37="","",D38^2) -> 0.012095551 | E43: =IF(E37="","",E38^2) -> 0.017574519 | F43: =IF(F37="","",F38^2) -> 0 | G43: =IF(G37="","",G38^2) -> 0 | H43: =IF(H37="","",H38^2) | I43: =IF(I37="","",I38^2) | J43: =IF(J37="","",J38^2) | ... L43: =IF(L37="","",L38^2)
A44: L1 Penalty | B44: =SUM(C44:L44) -> 0.012127435 | C44: =IF(OR(C37="",C41<>"YES"),0,$B$5*$B$6*C42) -> 0 | D44: =IF(OR(D37="",D41<>"YES"),0,$B$5*$B$6*D42) -> 0.0054989887 | E44: =IF(OR(E37="",E41<>"YES"),0,$B$5*$B$6*E42) -> 0.006628446 | F44: =IF(OR(F37="",F41<>"YES"),0,$B$5*$B$6*F42) -> 0 | G44: =IF(OR(G37="",G41<>"YES"),0,$B$5*$B$6*G42) -> 0 | H44: =IF(OR(H37="",H41<>"YES"),0,$B$5*$B$6*H42) -> 0 | I44: =IF(OR(I37="",I41<>"YES"),0,$B$5*$B$6*I42) -> 0 | J44: =IF(OR(J37="",J41<>"YES"),0,$B$5*$B$6*J42) -> 0 | ... L44: =IF(OR(L37="",L41<>"YES"),0,$B$5*$B$6*L42) -> 0
A45: L2 Penalty | B45: =SUM(C45:L45) -> 0.00074175173 | C45: =IF(OR(C37="",C41<>"YES"),0,0.5*$B$5*(1-$B$6)*C43) -> 0 | D45: =IF(OR(D37="",D41<>"YES"),0,0.5*$B$5*(1-$B$6)*D43) -> 0.00030238876 | E45: =IF(OR(E37="",E41<>"YES"),0,0.5*$B$5*(1-$B$6)*E43) -> 0.00043936297 | F45: =IF(OR(F37="",F41<>"YES"),0,0.5*$B$5*(1-$B$6)*F43) -> 0 | G45: =IF(OR(G37="",G41<>"YES"),0,0.5*$B$5*(1-$B$6)*G43) -> 0 | H45: =IF(OR(H37="",H41<>"YES"),0,0.5*$B$5*(1-$B$6)*H43) -> 0 | I45: =IF(OR(I37="",I41<>"YES"),0,0.5*$B$5*(1-$B$6)*I43) -> 0 | J45: =IF(OR(J37="",J41<>"YES"),0,0.5*$B$5*(1-$B$6)*J43) -> 0 | ... L45: =IF(OR(L37="",L41<>"YES"),0,0.5*$B$5*(1-$B$6)*L43) -> 0
A46: DF Loss | C46: =IF(C38=0,0,1) -> 1 | D46: =IF(D38=0,0,1) -> 1 | E46: =IF(E38=0,0,1) -> 1 | F46: =IF(F38=0,0,1) -> 0 | G46: =IF(G38=0,0,1) -> 0 | H46: =IF(H38=0,0,1) -> 0 | I46: =IF(I38=0,0,1) -> 0 | J46: =IF(J38=0,0,1) -> 0 | ... L46: =IF(L38=0,0,1) -> 0
...

Sheet Diagnostics
A1: Model Diagnostics
A3: FIT STATISTICS
A4: n (Observations) | B4: =Model!B17 -> 5
A5: p (Parameters) | B5: =Model!B18 -> 3
A6: Degrees of Freedom | B6: =B4-B5 -> 2
A7: Loss Function | B7: =Model!B7 -> SSE
A8: Alpha (α) | B8: =Model!B5 -> 0.1
A9: L1 Ratio | B9: =Model!B6 -> 0.5
A11: Total Loss (weighted) | B11: =Model!C11 -> 197.52929
A12: Total Penalty | B12: =Model!C14 -> 0.012869186
A13: ★ Objective Value | B13: =Model!C16 -> 197.54216
A15: SSE | B15: =SUMPRODUCT(IF(Model!B59:B63<>"",(Model!B59:B63)^2,0)) -> #VALUE!
A16: MSE | B16: =IFERROR(B15/B6,0) -> 0
A17: RMSE | B17: =IFERROR(SQRT(B16),0) -> 0
A18: MAE | B18: =IFERROR(SUMPRODUCT(IF(Model!B59:B63<>"",ABS(Model!B59:B63),0))/B4,0) -> 0
A20: Mean Y | B20: =AVERAGE(Model!E59:E63) -> 390
A21: SST | B21: =SUMPRODUCT(IF(Model!E59:E63<>"",(Model!E59:E63-B20)^2,0)) -> #VALUE!
A22: R² | B22: =IFERROR(1-B15/B21,0) -> 0
A23: Adj R² | B23: =IFERROR(1-(1-B22)*(B4-1)/B6,B22) -> -1
A25: MAPE (%) | B25: =IFERROR(SUMPRODUCT(IF(Model!B59:B63<>"",ABS(Model!B59:B63/IF(Model!E59:E63=0,1,Model!E59:E63)),0))/B4*100,0) -> 0
A26: SSPE | B26: =SUMPRODUCT(IF(Model!B59:B63<>"",(Model!B59:B63/IF(Model!E59:E63=0,1,Model!E59:E63))^2,0)) -> #VALUE!
A28: COEFFICIENT SUMMARY
A29: Name | B29: Value | C29: Lower Bound | D29: Upper Bound | E29: At Lower? | F29: At Upper? | G29: Penalized?
A30: =Model!C37 -> Intercept | B30: =Model!C38 -> 813.6692 | C30: =Model!C39 -> 0 | D30: =Model!C40 -> 10000000000 | E30: =IF(OR(Model!C37="",Model!C39=""),"",IF(ABS(Model!C38-Model!C39)<0.000001,"BINDING","")) | F30: =IF(OR(Model!C37="",Model!C40=""),"",IF(ABS(Model!C38-Model!C40)<0.000001,"BINDING","")) | G30: =Model!C41 -> NO
A31: =Model!D37 -> β₁ (LC) | B31: =Model!D38 -> -0.10997977 | C31: =Model!D39 -> -1 | D31: =Model!D40 -> 0 | E31: =IF(OR(Model!D37="",Model!D39=""),"",IF(ABS(Model!D38-Model!D39)<0.000001,"BINDING","")) | F31: =IF(OR(Model!D37="",Model!D40=""),"",IF(ABS(Model!D38-Model!D40)<0.000001,"BINDING","")) | G31: =Model!D41 -> YES
A32: =Model!E37 -> β₂ (RC) | B32: =Model!E38 -> -0.13256892 | C32: =Model!E39 -> -1 | D32: =Model!E40 -> 0 | E32: =IF(OR(Model!E37="",Model!E39=""),"",IF(ABS(Model!E38-Model!E39)<0.000001,"BINDING","")) | F32: =IF(OR(Model!E37="",Model!E40=""),"",IF(ABS(Model!E38-Model!E40)<0.000001,"BINDING","")) | G32: =Model!E41 -> YES
A33: =Model!F37 -> β₃ | B33: =Model!F38 -> 0 | C33: =Model!F39 -> 0 | D33: =Model!F40 -> 0 | E33: =IF(OR(Model!F37="",Model!F39=""),"",IF(ABS(Model!F38-Model!F39)<0.000001,"BINDING","")) -> BINDING | F33: =IF(OR(Model!F37="",Model!F40=""),"",IF(ABS(Model!F38-Model!F40)<0.000001,"BINDING","")) -> BINDING | G33: =Model!F41 -> YES
A34: =Model!G37 -> β₄ | B34: =Model!G38 -> 0 | C34: =Model!G39 -> 0 | D34: =Model!G40 -> 0 | E34: =IF(OR(Model!G37="",Model!G39=""),"",IF(ABS(Model!G38-Model!G39)<0.000001,"BINDING","")) -> BINDING | F34: =IF(OR(Model!G37="",Model!G40=""),"",IF(ABS(Model!G38-Model!G40)<0.000001,"BINDING","")) -> BINDING | G34: =Model!G41 -> YES
A35: =Model!H37 -> 0 | B35: =Model!H38 -> 0 | C35: =Model!H39 -> 0 | D35: =Model!H40 -> 0 | E35: =IF(OR(Model!H37="",Model!H39=""),"",IF(ABS(Model!H38-Model!H39)<0.000001,"BINDING","")) | F35: =IF(OR(Model!H37="",Model!H40=""),"",IF(ABS(Model!H38-Model!H40)<0.000001,"BINDING","")) | G35: =Model!H41 -> 0
A36: =Model!I37 -> 0 | B36: =Model!I38 -> 0 | C36: =Model!I39 -> 0 | D36: =Model!I40 -> 0 | E36: =IF(OR(Model!I37="",Model!I39=""),"",IF(ABS(Model!I38-Model!I39)<0.000001,"BINDING","")) | F36: =IF(OR(Model!I37="",Model!I40=""),"",IF(ABS(Model!I38-Model!I40)<0.000001,"BINDING","")) | G36: =Model!I41 -> 0
A37: =Model!J37 -> 0 | B37: =Model!J38 -> 0 | C37: =Model!J39 -> 0 | D37: =Model!J40 -> 0 | E37: =IF(OR(Model!J37="",Model!J39=""),"",IF(ABS(Model!J38-Model!J39)<0.000001,"BINDING","")) | F37: =IF(OR(Model!J37="",Model!J40=""),"",IF(ABS(Model!J38-Model!J40)<0.000001,"BINDING","")) | G37: =Model!J41 -> 0
A38: =Model!K37 -> 0 | B38: =Model!K38 -> 0 | C38: =Model!K39 -> 0 | D38: =Model!K40 -> 0 | E38: =IF(OR(Model!K37="",Model!K39=""),"",IF(ABS(Model!K38-Model!K39)<0.000001,"BINDING","")) | F38: =IF(OR(Model!K37="",Model!K40=""),"",IF(ABS(Model!K38-Model!K40)<0.000001,"BINDING","")) | G38: =Model!K41 -> 0
A39: =Model!L37 -> 0 | B39: =Model!L38 -> 0 | C39: =Model!L39 -> 0 | D39: =Model!L40 -> 0 | E39: =IF(OR(Model!L37="",Model!L39=""),"",IF(ABS(Model!L38-Model!L39)<0.000001,"BINDING","")) | F39: =IF(OR(Model!L37="",Model!L40=""),"",IF(ABS(Model!L38-Model!L40)<0.000001,"BINDING","")) | G39: =Model!L41 -> 0
A41: GENERALIZED DEGREES OF FREEDOM
A42: # Binding Constraints | B42: =COUNTIF(E30:E39,"BINDING")+COUNTIF(F30:F39,"BINDING") -> 4
A43: # Specified Bounds | B43: =COUNTA(Model!C39:L39)+COUNTA(Model!C40:L40) -> 20
A45: Eff. df (Gaines: binding) | B45: =B4-B5+B42 -> 6
A46: Eff. df (Hu: all specified) | B46: =B4-B5+B43 -> 22

Sheet Instructions
A1: Penalized-Constrained Regression Template — Instructions
A3: PURPOSE
A4: This template implements the Penalized-Constrained Regression framework from:
A5: Joy & Watstein (2026), 'Small Data, Big Problems: Can we Constrain the Chaos
A6: in Small, Correlated Datasets?' ICEAA Professional Development & Training Workshop.
A7: Python package: https://github.com/frankij11/Penalized-Constrained-Regression
A9: Formulation: minimize L(β) + α·l1_ratio·Σ|βⱼ| + ½·α·(1−l1_ratio)·Σβⱼ²
A10: subject to LB ≤ β ≤ UB and Aβ ≤/≥/= b
A12: SHEET LAYOUT
A13: Model: Everything — hyperparameters, objective, solver instructions,
A14: coefficients table (transposed), constraints table, and data table.
A15: Diagnostics: Fit statistics, coefficient summary, GDF, charts.
... A92: Non-linear models: Modify ŷ formula in column D to any functional form.
